Workbook

Sheet Claude Log
A1: Turn # | B1: Date | C1: User Request | D1: Action Taken | E1: Details | F1: Outcome
A2: 1 | B2: 46117 | C2: Deep analysis of workbook and plan upgrade with more detailed research and calculation tools | D2: Full audit of all 8 sheets; identified gaps in Dose Calculation sections 2-4 (empty data rows); proposed comprehensive upgrade plan | E2: Dose Calculation sheet has Section 1 (Fundamental Quantities) populated but Sections 2 (wR), 3 (wT), 4 (Dose Limits) have headers only with no data. Reference sheets (ICRP, IAEA, NCRP/ICRU, Physics Data, Degradation Products, Computational Tools) are all well-populated. | F2: Presented 3-phase upgrade plan: (1) Fill empty sections 2-4, (2) Add 6 interactive calculators, (3) Add Radionuclide Data reference sheet. Awaiting user confirmation.
A3: 3 | B3: 46117 | C3: User confirmed plan and asked to proceed with Phase 2 — wiring all 6 calculator sections with live formulas | D3: Wired formulas for all 6 calculator sections (S5-S10) on Dose Calculation sheet, formatted outputs, added sub-descriptions, updated Overview & Index with new Radionuclide Data sheet listing and colour-code legend entries for calculator cells | E3: S5 Point Source: VLOOKUP for Γ from Radionuclide Data, D=ΓA/d². S6 Inverse Square: D₂=D₁(d₁/d₂)². S7 Decay: VLOOKUP for t½ & λ, A(t)=A₀e^(-λt) with unit conversion. S8 Shielding: n=log₂(I₀/I), x=n×HVL, TVL calc. S9 Internal Dose: VLOOKUP ALI by pathway, E(50)=(I/ALI)×20mSv. S10 ALI/DAC: triple lookup (ALI_inh, ALI_ing, DAC), fraction-of-limit with 3-tier compliance flags. All formulas verified with test values. | F3: All 6 calculators operational with correct physics. Nuclide dropdowns linked to Radionuclide Data sheet. Overview updated with sheet 9 and new colour legend. Phase 2 complete.
A4: 3 | B4: 46118 | C4: User requested a comprehensive decay chain reference table covering all 4 natural series plus medical/industrial/reactor isotopes. | D4: Created new 'Decay Chains' sheet with 14 columns and ~128 rows of nuclear decay chain data. | E4: Built 4 natural chains: U-238 (15 nuclides→Pb-206), U-235 (12→Pb-207), Th-232 (12→Pb-208), Np-237 (14→Tl-205). Added medical isotopes (Mo-99/Tc-99m, F-18, Ga-67, Tl-201, I-131, I-125, Ir-192), fission/activation products (Cs-137, Sr-90, Co-60, Co-57, Cr-51, H-3, C-14, P-32), actinides (Pu-239→U-235 series, Am-241→Np-237 series), plus K-40, Rn-222, Xe-133, Fe-55, Ni-63, Mn-54, Zn-65, I-129, Tc-99. Color-coded sections, legend, and data source citations included. | F4: Comprehensive decay chain reference table complete in 'Decay Chains' sheet (A1:N152). Includes all branch points, energies, half-lives, and cross-references between chains.

Sheet Overview & Index
B2: ☢ RADIATION SAFETY & DOSE CALCULATION — CORE DOCUMENT LIBRARY
B3: Comprehensive reference library: physics fundamentals, dose calculation methods, degradation products, standards & computational tools
B4: Generated: 05 April 2026 | Sources: ICRP, IAEA, NCRP, ICRU, NRC, NIST, EPA
B7: # | C7: Sheet | D7: Topics Covered | E7: Key Subjects | F7: No. Documents
B8: 1 | C8: Overview & Index | D8: Navigation, colour coding, scope | E8: —
B9: 2 | C9: ICRP Publications | D9: Recommendations, dose limits, tissue weighting, RBE | E9: 150 pubs
B10: 3 | C10: IAEA Standards & Reports | D10: BSS, safety guides, safety reports, TRS dosimetry codes | E10: 35 docs
B11: 4 | C11: NCRP & ICRU Reports | D11: Shielding, measurement, units, dosimetry | E11: 28 docs
B12: 5 | C12: Dose Calculation Methods | D12: Absorbed dose, equivalent dose, effective dose, wR, wT, dose limits, 6 live calculators | E12: 10 quantities + 6 calculators
B13: 6 | C13: Radiation Physics Data | D13: Decay data, attenuation, cross sections, NIST databases | E13: 20 refs
B14: 7 | C14: Degradation Products | D14: Radiolysis, activation products, decay chains, Bateman eq. | E14: 22 docs
B15: 8 | C15: Computational Tools | D15: Monte Carlo codes, deterministic codes, online calculators | E15: 15 tools
B16: 9 | C16: Radionuclide Data | D16: Half-lives, decay modes, gamma energies, Γ factors, specific activities, ALI, DAC | E16: 20 nuclides
B18: COLOUR CODING LEGEND
C19: ★ KEY / Foundational document — must-read cornerstone reference
C20: Dose calculation formula or computational method
C21: Radiation degradation product or activation analysis
C22: Monte Carlo / computational transport code
C23: General reference document
C25: Calculator input cell — user enters values here
C26: Calculator output cell — computed from formula

Sheet ICRP Publications
B2: ICRP Publications — International Commission on Radiological Protection
B3: Cornerstone international recommendations for radiological protection physics. ★ = foundational document.
B5: Pub # | C5: Publication Title | D5: Year | E5: Category | F5: Key Physics Content | G5: Relevance to Dose Calc | H5: DOI / URL
B6: ICRP 26 | C6: Recommendations of the ICRP | D6: 1977 | E6: ★ Foundational | F6: Introduced effective dose equivalent; dose limits 50 mSv/y occupational, 5 mSv/y public | G6: Basis of all occupational dose limits; first formal weighting factors | H6: → ICRP
B7: ICRP 30 | C7: Limits for Intakes of Radionuclides by Workers (Parts 1–4) | D7: 1979 | E7: ★ Internal Dosimetry | F7: ALI, DAC, committed dose equivalent; biokinetic models; dose conversion factors per radionuclide | G7: Internal dose calculation: H₅₀,T = ΣᵢAᵢ·SEE(T←S)·Δᵢ·ϕ(T←S)/mT | H7: → ICRP
B8: ICRP 38 | C8: Radionuclide Transformations — Energy and Intensity of Emissions | D8: 1983 | E8: Nuclear Data | F8: Decay data: decay energies, branching ratios, emission intensities for 800+ radionuclides | G8: Required for all source-term and internal dosimetry calculations | H8: → ICRP
B9: ICRP 51 | C9: Data for Use in Protection Against External Radiation | D9: 1987 | E9: External Dosimetry | F9: Fluence-to-dose conversion factors; AP, PA, LAT, ROT geometries; photons, electrons, neutrons | G9: External dose rate calculations: Ḣ*(10) = Φ·h_Φ; shielding design | H9: → ICRP
B10: ICRP 58 | C10: RBE for Deterministic Effects | D10: 1989 | E10: Radiobiology | F10: Relative Biological Effectiveness for tissue reactions; RBE-weighted dose | G10: Threshold doses for deterministic effects; RBE factors for non-stochastic injuries | H10: → ICRP
B11: ICRP 60 | C11: 1990 Recommendations of the ICRP | D11: 1991 | E11: ★ Foundational | F11: Revised wR, wT; effective dose E=ΣT wT·HT; 20 mSv/y occupational; ALARA principle | G11: Current European regulatory basis; tissue weighting factors; dose limits | H11: → ICRP
B12: ICRP 66 | C12: Human Respiratory Tract Model for Radiological Protection | D12: 1994 | E12: Biokinetics | F12: HRTM: deposition fractions, clearance rates, absorption types F/M/S for inhaled particles | G12: Inhalation dose calculation; lung dose from airborne radionuclides | H12: → ICRP
B13: ICRP 68 | C13: Dose Coefficients for Intakes of Radionuclides by Workers | D13: 1994 | E13: ★ Internal Dosimetry | F13: e(50) values (Sv/Bq) for inhalation and ingestion; all major occupational radionuclides | G13: Direct lookup: committed effective dose E₅₀ = e(50)·Intake[Bq] | H13: → ICRP
B14: ICRP 72 | C14: Age-dependent Doses — Part 5: Compilation of Ingestion & Inhalation | D14: 1996 | E14: Internal Dosimetry | F14: Dose coefficients for public (infants to adults); age-specific biokinetic models | G14: Public dose: E = e(g)·Intake; children's doses from environmental contamination | H14: → ICRP
B15: ICRP 74 | C15: Conversion Coefficients for Radiological Protection vs External Radiation | D15: 1996 | E15: External Dosimetry | F15: h_Φ(E) factors for photons, electrons, neutrons, protons; organ doses per fluence | G15: Ambient dose equivalent H*(10); directional dose equivalent H'(0.07) | H15: → ICRP
B16: ICRP 89 | C16: Basic Anatomical & Physiological Data — Reference Values | D16: 2002 | E16: Reference Data | F16: Reference Man/Woman/Child anatomical parameters; organ masses, volumes, elemental composition | G16: Required for dosimetric model geometry and biokinetic parameter derivation | H16: → ICRP
... B31: ICRP 147 | C31: Use of Dose Quantities in Radiological Protection | D31: 2021 | E31: ★ Foundational | F31: Clarifies role of protection quantities vs measurable quantities; effective dose as risk indicator | G31: Definitive guidance on when to use absorbed vs equivalent vs effective dose | H31: → ICRP

Sheet IAEA Standards
B2: IAEA Safety Standards & Technical Reports — International Atomic Energy Agency
B3: Binding safety standards (GSR, SSR, GSG, SSG), Safety Reports Series (SRS) and Technical Reports Series (TRS).
B5: Doc ID | C5: Title | D5: Year | E5: Series | F5: Key Content | G5: Dose Calc Relevance | H5: Link
B6: GSR Part 3 | C6: Radiation Protection and Safety of Radiation Sources: International Basic Safety Standards | D6: 2014 | E6: ★ General Safety Req. | F6: Dose limits: 20 mSv/y occupational; 1 mSv/y public; exclusion/exemption levels; source control requirements | G6: Regulatory dose limits and constraints; framework for all dose assessments | H6: → IAEA
B7: TRS-398 | C7: Absorbed Dose Determination in External Beam Radiotherapy | D7: 2000 | E7: ★ Technical Report | F7: Code of practice for dosimetry; ionization chamber calibration; kQ correction factors; beam quality specification | G7: Reference absorbed dose to water: Dw,Q = MQ·ND,w,Q₀·kQ,Q₀; calibration chain | H7: → IAEA
B8: TRS-277 | C8: Absorbed Dose Determination in Photon and Electron Beams | D8: 1987 | E8: Technical Report | F8: Exposure-based dosimetry; C_λ factors; predecessor to TRS-398 for photon beams | G8: Historical reference for absorbed dose from exposure measurements | H8: → IAEA
B9: TRS-457 | C9: Dosimetry in Diagnostic Radiology | D9: 2007 | E9: Technical Report | F9: Air kerma and dose-area product; kVp spectra; HVL measurements; patient dose estimation in X-ray | G9: Diagnostic dose quantities: Ka,e entrance kerma, Ka,i incident kerma, KAP | H9: → IAEA
B10: SRS-47 | C10: Radiation Protection in the Design of Radiotherapy Facilities | D10: 2006 | E10: Safety Reports | F10: Shielding design for linacs and cobalt; workload W, occupancy T, use factor U; primary/secondary barriers | G10: Barrier transmission: B = P·d²/(W·U·T); shielding thickness calculation | H10: → IAEA
B11: SRS-16 | C11: Calibration of Radiation Protection Monitoring Instruments | D11: 2000 | E11: Safety Reports | F11: Calibration standards for survey meters and dosimeters; reference fields; calibration chain | G11: Instrument calibration methodology for dose rate measurements | H11: → IAEA
B12: GSG-7 | C12: Occupational Radiation Protection | D12: 2018 | E12: General Safety Guide | F12: Workplace monitoring; dose records; classification of areas; personal dosimetry; dose assessment procedures | G12: Operational radiation protection; monitoring programme design; HPZ/SPZ classification | H12: → IAEA
B13: GSG-2 | C13: Criteria for Use in Emergency Exposure Situations | D13: 2011 | E13: General Safety Guide | F13: Generic action levels; protective action criteria; dose assessment in nuclear emergencies | G13: Emergency dose assessments: operational intervention levels, dose projection methods | H13: → IAEA
B14: TECDOC-1162 | C14: Generic Models for Use in Assessing the Impact of Discharges of Radioactive Substances | D14: 2001 | E14: TECDOC | F14: Environmental transport models; dilution factors; ingestion dose from food chain; immersion dose | G14: Public dose from effluent releases: Eₚ = Σ Qᵢ·DCFᵢ·CFᵢ (discharge×dose coefficient×concentration factor) | H14: → IAEA
B15: SRS-44 | C15: Radiation Protection and Safety in Industrial Radiography | D15: 2011 | E15: Safety Reports | F15: Source strength, distance calculations, shielding for industrial γ-sources; controlled/supervised zones | G15: Inverse square law dose rates: Ḣ = A·Γ/d²; HDR shielding calculations | H15: → IAEA
B16: TRS-424 | C16: Radiation Biology: A Handbook for Teachers and Students | D16: 2010 | E16: Technical Report | F16: Radiobiology mechanisms; cell survival curves; LQ model; DNA damage; dose-response relationships | G16: LQ model: SF = exp(−αD − βD²); basis for deterministic/stochastic risk assessment | H16: → IAEA
... B21: SRS-37 | C21: Methods for Assessing Occupational Radiation Doses Due to Intakes of Radionuclides | D21: 2004 | E21: Safety Reports | F21: Bioassay monitoring; urinary/fecal excretion models; chest counting; m(T) retention functions | G21: Dose from bioassay: H₅₀,T = m_obs/m_unit × (H₅₀,T per unit intake) | H21: → IAEA

Sheet NCRP & ICRU Reports
B2: NCRP Reports & ICRU Reports — US Radiation Protection Standards and Measurement Units
B3: NCRP = National Council on Radiation Protection | ICRU = International Commission on Radiation Units & Measurements
B5: Report | C5: Title | D5: Year | E5: Body | F5: Key Physics Content | G5: Dose Calc Application | H5: Access
B6: NCRP 49 | C6: Structural Shielding Design and Evaluation for Medical Use of X-Rays and Gamma Rays | D6: 1976 | E6: NCRP | F6: Primary/secondary barrier calculation; workload W; B=P·d²/(W·U·T); occupancy factors | G6: Classic shielding design method; transmission factors; energy-dependent HVL tables | H6: → Link
B7: NCRP 82 | C7: SI Units in Radiation Protection and Measurements | D7: 1982 | E7: NCRP | F7: Gray, Sievert, Becquerel, Coulomb/kg; conversion factors from old to SI units | G7: Unit conversion reference: 1 Gy=100 rad; 1 Sv=100 rem; 1 Bq=2.703×10⁻¹¹ Ci | H7: → Link
B8: NCRP 116 | C8: Limitation of Exposure to Ionizing Radiation | D8: 1993 | E8: ★ NCRP | F8: US dose limits: 50 mSv/y occupational; 1 mSv/y public; ALARA; lens 150 mSv/y | G8: US regulatory dose limit framework; basis for 10 CFR 20 (NRC) and 10 CFR 835 (DOE) | H8: → Link
B9: NCRP 147 | C9: Structural Shielding Design for Medical X-Ray Imaging Facilities | D9: 2004 | E9: ★ NCRP | F9: Updated shielding method; transmission factor B(TVL₁,TVLₑ); kVp-dependent data; new design goals | G9: Modern diagnostic shielding: P=0.1 mGy/wk controlled; T occupancy factors; scatter fractions | H9: → Link
B10: NCRP 151 | C10: Structural Shielding Design and Evaluation for MV X-Ray and Gamma-Ray Radiotherapy Facilities | D10: 2005 | E10: ★ NCRP | F10: MV photon and neutron shielding; TVL₁/TVLₑ; primary/secondary barriers; maze design | G10: Linac shielding: barrier thickness x = TVL₁+(log₁₀B−1)TVLₑ; neutron capture gamma | H10: → Link
B11: NCRP 160 | C11: Ionizing Radiation Exposure of the Population of the United States | D11: 2009 | E11: NCRP | F11: US population dose inventory: background 3.1 mSv/y; medical 3.0 mSv/y; radon 2.3 mSv/y | G11: Dose inventory benchmarking; natural background component breakdown | H11: → Link
B12: NCRP 174 | C12: Preconception and Prenatal Radiation Exposure: Health Effects and Protective Guidance | D12: 2013 | E12: NCRP | F12: Embryo/fetal dose limits; organogenesis dose thresholds; pregnancy declaration guidance | G12: Fetal dose limit 0.5 mGy/month after declaration; embryonic risk dose-response | H12: → Link
B13: ICRU 33 | C13: Radiation Quantities and Units | D13: 1980 | E13: ★ ICRU | F13: Formal definitions: absorbed dose D (Gy), kerma K, fluence Φ, exposure X; historical SI conversion | G13: Foundational quantity definitions underpinning all radiation dosimetry calculations | H13: → Link
B14: ICRU 51 | C14: Quantities and Units in Radiation Protection Dosimetry | D14: 1993 | E14: ICRU | F14: Operational protection quantities: H*(10), Hp(10), H'(0.07,Ω); conversion from fluence | G14: Defines measurable quantities for area and personal dosimetry; links to physical quantities | H14: → Link
B15: ICRU 57 | C15: Conversion Coefficients for Use in Radiological Protection against External Radiation | D15: 1998 | E15: ICRU | F15: h_Φ,H*(10) vs photon/neutron energy; AP, PA, LAT, ROT irradiation geometries | G15: Area monitor calibration; h_Φ(E) lookup for Ḣ*(10)=Φ·h_Φ; phantom geometry factors | H15: → Link
B16: ICRU 85a | C16: Fundamental Quantities and Units for Ionizing Radiation (Revised) | D16: 2011 | E16: ★ ICRU | F16: Revised formal definitions: absorbed dose, LET, stopping power, stochastic quantities | G16: Current reference for all dosimetric quantity definitions; LET-D and LET-T; track structure | H16: → Link
... B20: NCRP 128 | C20: Radionuclide Exposure of the Embryo/Fetus | D20: 1998 | E20: NCRP | F20: Placental transfer of radionuclides; fetal dose coefficients; committed dose in utero | G20: Embryo/fetal dose from maternal intake: Hfetus = Σ CF(T,nucl)·Intake | H20: → Link

Sheet Dose Calculation
B2: Radiation Dose Calculation Methods — Formulae, Quantities & Calculation Pathways
B3: Green = formula-based; Yellow = key quantity definition. All quantities from ICRP 103 & ICRU 85a.
B5: 1. FUNDAMENTAL DOSE QUANTITIES
B6: Quantity | C6: Symbol | D6: Unit (SI) | E6: Formula | F6: Description | G6: ICRP/ICRU Reference | H6: Notes
B7: Absorbed Dose | C7: D | D7: Gray (Gy = J/kg) | E7: D = dE/dm | F7: Mean energy imparted by ionizing radiation per unit mass of material | G7: ICRU 85a; ICRP 103 §B.1 | H7: Measurable physical quantity. Foundation of all dose calculations. 1 Gy = 1 J/kg
B8: Kerma | C8: K | D8: Gray (Gy) | E8: K = dEtr/dm | F8: Kinetic energy released per unit mass in uncharged particle interactions | G8: ICRU 85a §3; ICRP 103 | H8: Approximates absorbed dose in CPE conditions. K_col ≈ D for photons in tissue
B9: Equivalent Dose | C9: HT | D9: Sievert (Sv) | E9: HT = ΣR wR·DT,R | F9: Absorbed dose weighted by radiation quality factor to reflect biological effectiveness | G9: ★ ICRP 103 §B.2; ICRU 51 | H9: wR: γ,X,β=1; p=2; n=2.5–20(E); α=20. For protection only — not measurable
B10: Effective Dose | C10: E | D10: Sievert (Sv) | E10: E = ΣT wT·HT | F10: Sum of weighted equivalent doses to all organs/tissues; indicator of stochastic risk | G10: ★ ICRP 103 §B.3; ICRP 147 | H10: wT: gonads=0.08; bone marrow/lung/colon/stomach/breast=0.12; remainder=0.12
B11: Committed Equiv. Dose | C11: H(T,τ) | D11: Sievert (Sv) | E11: H(T,50) = ∫₀⁵⁰ ḢT(t)dt | F11: Time-integrated equivalent dose to organ T following radionuclide intake; τ=50 y adults | G11: ICRP 103 §B.5; ICRP 30 Part 1 | H11: Assigned to year of intake. τ=70 y for children. Internal exposure metric
B12: Committed Eff. Dose | C12: E(τ) | D12: Sievert (Sv) | E12: E(50) = ΣT wT·H(T,50) | F12: Committed effective dose = sum of wT-weighted committed equivalent doses over 50 years | G12: ★ ICRP 103; ICRP 130 | H12: Practical internal dosimetry quantity for workers: E(50) = e(50)·I where I is intake
B13: Dose Equivalent | C13: H | D13: Sievert (Sv) | E13: H = D·Q | F13: Absorbed dose multiplied by quality factor Q; older ICRU operational quantity | G13: ICRU 51; NCRP 116 | H13: Q depends on unrestricted LET in water. H*(10), Hp(10) are operational quantities
B14: Ambient Dose Equiv. | C14: H*(10) | D14: Sievert (Sv) | E14: H*(10) = Φ·h_Φ(E) | F14: Dose equivalent in ICRU sphere at 10 mm depth; used for area monitoring | G14: ICRU 57; ICRP 116 | H14: Measurable operational quantity. h_Φ(E) from ICRU 57 / ICRP 116 tables
B15: Dose Rate | C15: Ḣ | D15: Sv/h or mSv/y | E15: Ḣ = dH/dt | F15: Rate of dose equivalent accumulation per unit time | G15: ICRU 33; ICRP 103 | H15: Point source: Ḣ = A·Γ/d². Gamma constant Γ tabulated per radionuclide
B18: 2. RADIATION WEIGHTING FACTORS (wR) — ICRP 103, Table A.1
B19: Radiation Type | C19: Energy Range | D19: wR Value | E19: Notes
B20: Photons (all energies) | C20: All | D20: 1 | E20: Includes X-rays, γ-rays; independent of energy
B21: Electrons & muons (all energies) | C21: All | D21: 1 | E21: Includes β⁻, β⁺, Auger electrons
B22: Protons & charged pions | C22: > 2 MeV | D22: 2 | E22: New in ICRP 103; previously wR=5 in ICRP 60
B23: Alpha particles, fission fragments, heavy ions | C23: All | D23: 20 | E23: Highest wR; high-LET radiation; RBE >> 1
B24: Neutrons (< 1 MeV) | C24: < 1 MeV | D24: 2.5 – 5.0 | E24: Continuous function of energy per ICRP 103 Eq. A.1
B25: Neutrons (1 MeV – 50 MeV) | C25: 1 – 50 MeV | D25: 5.0 – 20.0 | E25: Peak wR ≈ 20 near 1 MeV; falls at higher energies
B26: Neutrons (> 50 MeV) | C26: > 50 MeV | D26: 5.0 – 2.5 | E26: Decreases at very high energies; same formula
B27: Neutron wR formula (ICRP 103) | C27: All En | D27: Eq. A.1 | E27: wR = 2.5 + 18.2·exp(−[ln(En)]²/6) for En in MeV
B30: 3. TISSUE WEIGHTING FACTORS (wT) — ICRP 103, Table A.2 [ΣwT = 1.00]
B31: Tissue/Organ | C31: wT (ICRP 103) | D31: wT (ICRP 60) | E31: No. Tissues | F31: Comment
B32: Bone marrow (red) | C32: 0.12 | D32: 0.12 | E32: 1 | F32: Unchanged from ICRP 60
B33: Colon | C33: 0.12 | D33: — | E33: 1 | F33: New in ICRP 103 (was part of 'remainder' in ICRP 60)
B34: Lung | C34: 0.12 | D34: 0.12 | E34: 1 | F34: Unchanged from ICRP 60
B35: Stomach | C35: 0.12 | D35: 0.12 | E35: 1 | F35: Unchanged from ICRP 60
B36: Breast | C36: 0.12 | D36: 0.05 | E36: 1 | F36: Increased from 0.05 → 0.12 in ICRP 103
B37: ΣwT (0.12 group) | C37: 0.6 | D37: — | E37: 5 | F37: Subtotal: 5 tissues × 0.12 = 0.60
B38: Gonads | C38: 0.08 | D38: 0.2 | E38: 1 | F38: Decreased from 0.20 → 0.08 in ICRP 103
B39: Bladder | C39: 0.04 | D39: 0.05 | E39: 1 | F39: Slightly reduced from ICRP 60
B40: Oesophagus | C40: 0.04 | D40: 0.05 | E40: 1 | F40: Slightly reduced from ICRP 60
B41: Liver | C41: 0.04 | D41: 0.05 | E41: 1 | F41: Slightly reduced from ICRP 60
B42: Thyroid | C42: 0.04 | D42: 0.05 | E42: 1 | F42: Slightly reduced from ICRP 60
B43: ΣwT (0.04 group) | C43: 0.2 | D43: — | E43: 5 | F43: Subtotal: 5 tissues × 0.04 = 0.20
B44: Bone surface | C44: 0.01 | D44: 0.01 | E44: 1 | F44: Unchanged from ICRP 60
B45: Brain | C45: 0.01 | D45: — | E45: 1 | F45: New in ICRP 103
B46: Salivary glands | C46: 0.01 | D46: — | E46: 1 | F46: New in ICRP 103
...

Sheet Radiation Physics Data
B2: Radiation Physics Data — Nuclear Data, Attenuation Coefficients, Cross-Sections & Online Databases
B3: Essential numerical datasets and tools for shielding, dosimetry, and transport calculations.
B5: Source / Database | C5: Organization | D5: Content / Data Type | E5: Energy Range | F5: Key Formula / Parameter | G5: Application | H5: URL / Access
B6: NIST XCOM | C6: NIST (USA) | D6: Photon cross sections (coherent scatter, Compton, PE, pair production, total μ/ρ) for Z=1–100 | E6: 1 keV – 100 GeV | F6: μ/ρ (cm²/g); I = I₀·exp(−μ/ρ·ρx) | G6: Gamma shielding; attenuation calculation; buildup factor input | H6: → Access
B7: NIST ESTAR/PSTAR/ASTAR | C7: NIST (USA) | D7: Stopping powers and ranges for electrons (ESTAR), protons (PSTAR), alpha (ASTAR) in materials | E7: 0.001–10,000 MeV | F7: S/ρ = −(1/ρ)dE/dx [MeV·cm²/g]; CSDA range | G7: Beta/electron/proton dose; range calculations; EBT films | H7: → Access
B8: NIST X-Ray Attenuation Coeff. | C8: NIST (USA) | D8: μ/ρ and μen/ρ for elements Z=1–92 and 48 dosimetric compounds; tabulated vs photon energy | E8: 1 keV – 20 MeV | F8: Kerma: K = Φ·E·(μen/ρ)·ρ/ρair×Wair/e | G8: Tissue kerma and dose calculations; Γ constant derivation | H8: → Access
B9: NNDC NuDat 3.0 | C9: NNDC/BNL (USA) | D9: Nuclide properties: half-lives, decay modes, Q-values, γ-ray energies & intensities, parent/daughter | E9: All radionuclides | F9: λ = ln2/T½; A = A₀·exp(−λt) | G9: Decay chain analysis; source activity calculation; shielding design | H9: → Access
B10: NNDC Chart of Nuclides | C10: NNDC/BNL (USA) | D10: Interactive nuclide chart; decay modes; stable isotopes; neutron cross sections | E10: Full chart of nuclides | F10: Z, N, A; binding energy per nucleon | G10: Quick reference for all nuclide properties; activation product ID | H10: → Access
B11: ICRP 107 Decay Data | C11: ICRP | D11: Decay data for 1252 radionuclides; α/β/γ/X/Auger energies; branching fractions; yields per decay | E11: All dosimetric radionuclides | F11: Δᵢ = fᵢ·Eᵢ·kᵢ (mean energy per decay type i) | G11: S-value and internal dosimetry; source term for MC codes | H11: → Access
B12: ENDF/B-VIII.0 | C12: CSEWG/BNL (USA) | D12: Evaluated nuclear data: neutron cross sections, fission yields, decay data, photon interaction data | E12: 0 to 20 MeV neutrons | F12: σ(E) in barns; reaction rate R = n·v·σ | G12: Neutron transport; activation calculations; reactor physics | H12: → Access
B13: JEFF 3.3 | C13: NEA/OECD (Europe) | D13: European nuclear data library: decay data, fission yields, activation cross sections | E13: Thermal to 20 MeV | F13: Activation: A = N·σ·Φ·(1−exp(−λt)) | G13: European reactor calculations; activation product inventories | H13: → Access
B14: JAERI/JENDL 5 | C14: JAEA (Japan) | D14: Japanese nuclear data; thermal and fast neutron cross sections; photon data | E14: Full energy range | F14: Microscopic/macroscopic cross sections | G14: Asian nuclear facility design; activation analysis | H14: → Access
B15: NIST Radiation Dosimetry Research | C15: NIST (USA) | D15: Dosimetric data: w_air values, g-values (water radiolysis), stopping powers, LET tables | E15: Broad range | F15: w_air=33.97 eV (ICRU 90); g(H₂O₂)=0.075 μmol/J | G15: Ionization chamber calibration; water radiolysis G-values | H15: → Access
B16: RADIOLOGICA / ICRP OIR Tool | C16: ICRP Online | D16: Interactive internal dosimetry: dose coefficients from ICRP Pub.130–137; biokinetic model outputs | E16: Occupational workers | F16: e(50) [Sv/Bq] for inhalation, ingestion, injection by radionuclide | G16: Worker dose from bioassay; inhalation dose calculation | H16: → Access
... B22: NIST STAR (Charged Particle) | C22: NIST (USA) | D22: Stopping powers for ions: Bethe-Bloch formula data; mass stopping powers; CSDA ranges | E22: 0.001–10,000 MeV | F22: Bethe-Bloch: −dE/dx=4πe⁴z²N/m_e v² × [ln(2m_e v²/I)−ln(1−β²)−β²] | G22: Heavy ion therapy dosimetry; proton range calculation; NORM | H22: → Access

Sheet Radionuclide Data
A1: RADIONUCLIDE PHYSICAL DATA — REFERENCE TABLE
A2: Source: ICRP 107 (2008), NNDC/BNL Evaluated Nuclear Structure Data File, NIST XCOM
A4: Nuclide | B4: Symbol | C4: Half-Life | D4: Half-Life (s) | E4: λ (s⁻¹) | F4: Decay Mode | G4: Eγ (MeV) | H4: Γ (R·cm²/mCi·h) | I4: Sp. Activity (Ci/g) | J4: ALI Inhal. (μCi) | K4: ALI Ingest. (μCi) | L4: DAC (μCi/mL)
A5: Hydrogen-3 | B5: H-3 | C5: 12.32 y | D5: 388800000 | E5: =LN(2)/D5 -> 1.782786e-09 | F5: β⁻ | G5: — | H5: — | I5: 9700 | J5: 80000 | K5: 80000 | L5: 2e-05
A6: Carbon-14 | B6: C-14 | C6: 5730 y | D6: 180700000000 | E6: =LN(2)/D6 -> 3.8359003e-12 | F6: β⁻ | G6: — | H6: — | I6: 4.46 | J6: 2000 | K6: 2000 | L6: 16
A7: Fluorine-18 | B7: F-18 | C7: 109.77 min | D7: 6586.2 | E7: =LN(2)/D7 -> 0.00010524235 | F7: β⁺, EC | G7: 0.511 | H7: 5.73 | I7: 95200000 | J7: 40000 | K7: 60000 | L7: 2e-05
A8: Phosphorus-32 | B8: P-32 | C8: 14.26 d | D8: 1231900 | E8: =LN(2)/D8 -> 5.6266514e-07 | F8: β⁻ | G8: — | H8: — | I8: 285700 | J8: 600 | K8: 900 | L8: 37
A9: Chromium-51 | B9: Cr-51 | C9: 27.70 d | D9: 2393300 | E9: =LN(2)/D9 -> 2.8961985e-07 | F9: EC | G9: 0.32 | H9: 0.18 | I9: 92400 | J9: 40000 | K9: 50000 | L9: 2e-05
A10: Cobalt-57 | B10: Co-57 | C10: 271.74 d | D10: 23478300 | E10: =LN(2)/D10 -> 2.9522886e-08 | F10: EC | G10: 0.122 | H10: 0.56 | I10: 8460 | J10: 6000 | K10: 10000 | L10: 26
A11: Cobalt-60 | B11: Co-60 | C11: 5.271 y | D11: 166300000 | E11: =LN(2)/D11 -> 4.1680528e-09 | F11: β⁻ | G11: 1.17, 1.33 | H11: 13.2 | I11: 1131 | J11: 30 | K11: 200 | L11: 18
A12: Gallium-67 | B12: Ga-67 | C12: 3.261 d | D12: 281800 | E12: =LN(2)/D12 -> 2.4597132e-06 | F12: EC | G12: 0.093, 0.185, 0.300 | H12: 0.76 | I12: 597000 | J12: 9000 | K12: 9000 | L12: 46
A13: Strontium-90 | B13: Sr-90 | C13: 28.80 y | D13: 908400000 | E13: =LN(2)/D13 -> 7.6304181e-10 | F13: β⁻ | G13: — | H13: — | I13: 137 | J13: 20 | K13: 30 | L13: 89
A14: Technetium-99m | B14: Tc-99m | C14: 6.01 h | D14: 21636 | E14: =LN(2)/D14 -> 3.2036753e-05 | F14: IT | G14: 0.14 | H14: 0.78 | I14: 5270000 | J14: 200000 | K14: 200000 | L14: 8e-05
A15: Iodine-125 | B15: I-125 | C15: 59.40 d | D15: 5132200 | E15: =LN(2)/D15 -> 1.3505849e-07 | F15: EC | G15: 0.035 | H15: 0.7 | I15: 17400 | J15: 60 | K15: 40 | L15: 38
A16: Iodine-131 | B16: I-131 | C16: 8.025 d | D16: 693400 | E16: =LN(2)/D16 -> 9.9963539e-07 | F16: β⁻ | G16: 0.364 | H16: 2.17 | I16: 124000 | J16: 50 | K16: 30 | L16: 28
A17: Cesium-137 | B17: Cs-137 | C17: 30.07 y | D17: 948600000 | E17: =LN(2)/D17 -> 7.3070544e-10 | F17: β⁻ | G17: 0.662 | H17: 3.26 | I17: 86.8 | J17: 200 | K17: 100 | L17: 68
A18: Iridium-192 | B18: Ir-192 | C18: 73.83 d | D18: 6379000 | E18: =LN(2)/D18 -> 1.0866079e-07 | F18: β⁻, EC | G18: 0.296–0.612 | H18: 4.69 | I18: 9210 | J18: 300 | K18: 400 | L18: 17
A19: Thallium-201 | B19: Tl-201 | C19: 3.038 d | D19: 262500 | E19: =LN(2)/D19 -> 2.6405607e-06 | F19: EC | G19: 0.068–0.167 | H19: 0.45 | I19: 636000 | J19: 30000 | K19: 40000 | L19: 1e-05
A20: Radium-226 | B20: Ra-226 | C20: 1600 y | D20: 50460000000 | E20: =LN(2)/D20 -> 1.3736567e-11 | F20: α | G20: 0.186 + daughters | H20: 8.25 | I20: 0.989 | J20: 3 | K20: 5 | L20: 19
A21: Uranium-235 | B21: U-235 | C21: 7.04E+08 y | D21: 2.2216 | E21: =LN(2)/D21 -> 0.31200359 | F21: α | G21: 0.186 | H21: 0.15 | I21: 2.176 | J21: 0.2 | K21: 0.6 | L21: 811
A22: Uranium-238 | B22: U-238 | C22: 4.47E+09 y | D22: 1.4117 | E22: =LN(2)/D22 -> 0.49100176 | F22: α | G22: — | H22: — | I22: 3.367 | J22: 0.2 | K22: 0.6 | L22: 611
A23: Plutonium-239 | B23: Pu-239 | C23: 24110 y | D23: 760600000000 | E23: =LN(2)/D23 -> 9.113163e-13 | F23: α | G23: — | H23: — | I23: 0.0621 | J23: 0.006 | K23: 0.04 | L23: 312
A24: Americium-241 | B24: Am-241 | C24: 432.2 y | D24: 13630000000 | E24: =LN(2)/D24 -> 5.0854525e-11 | F24: α | G24: 0.0595 | H24: 0.14 | I24: 3.43 | J24: 0.006 | K24: 0.04 | L24: 312

Sheet Decay Chains
A1: RADIONUCLIDE DECAY CHAINS — COMPREHENSIVE REFERENCE TABLE
A2: Source: ICRP 107 (2008), NNDC/BNL Chart of Nuclides (NuDat 3.0), ENSDF, Brookhaven National Laboratory
A3: Decay modes: α = alpha, β⁻ = beta-minus, β⁺ = beta-plus/positron, EC = electron capture, IT = isomeric transition, SF = spontaneous fission
A5: Chain / Series | B5: Nuclide | C5: Symbol | D5: Z | E5: A | F5: N | G5: Half-Life | H5: Decay Mode | I5: Branch % | J5: Eα/Eβ (MeV) | K5: Eγ (MeV) | L5: Daughter Product | M5: Step # | N5: Notes / Equilibrium
A6: URANIUM-238 SERIES (4n+2) | N6: Also called Radium series; ends at Pb-206
A7: U-238 Series | B7: Uranium-238 | C7: U-238 | D7: 92 | E7: 238 | F7: 146 | G7: 4.468 × 10⁹ y | H7: α | I7: 1 | J7: 4.27 | K7: 0.049 | L7: Th-234 | M7: 1 | N7: Primordial; most abundant U isotope (99.27%)
A8: U-238 Series | B8: Thorium-234 | C8: Th-234 | D8: 90 | E8: 234 | F8: 144 | G8: 24.10 d | H8: β⁻ | I8: 1 | J8: 0.198 | K8: 0.093 | L8: Pa-234m | M8: 2 | N8: Secular equilibrium with U-238
A9: U-238 Series | B9: Protactinium-234m | C9: Pa-234m | D9: 91 | E9: 234 | F9: 143 | G9: 1.17 min | H9: β⁻ | I9: 0.9984 | J9: 2.29 | K9: 1.001 | L9: U-234 | M9: 3 | N9: 0.16% IT branch → Pa-234 (6.7h)
A10: U-238 Series | B10: Uranium-234 | C10: U-234 | D10: 92 | E10: 234 | F10: 142 | G10: 2.455 × 10⁵ y | H10: α | I10: 1 | J10: 4.859 | K10: 0.053 | L10: Th-230 | M10: 4 | N10: Secular equilibrium with U-238 in aged ores
A11: U-238 Series | B11: Thorium-230 | C11: Th-230 | D11: 90 | E11: 230 | F11: 140 | G11: 7.538 × 10⁴ y | H11: α | I11: 1 | J11: 4.77 | K11: 0.068 | L11: Ra-226 | M11: 5 | N11: Also called ionium; ocean sediment dating
A12: U-238 Series | B12: Radium-226 | C12: Ra-226 | D12: 88 | E12: 226 | F12: 138 | G12: 1600 y | H12: α | I12: 1 | J12: 4.871 | K12: 0.186 | L12: Rn-222 | M12: 6 | N12: Principal source of radon gas; high Γ factor
A13: U-238 Series | B13: Radon-222 | C13: Rn-222 | D13: 86 | E13: 222 | F13: 136 | G13: 3.8235 d | H13: α | I13: 1 | J13: 5.59 | K13: 0.51 | L13: Po-218 | M13: 7 | N13: Noble gas; indoor air hazard; lung dose
A14: U-238 Series | B14: Polonium-218 | C14: Po-218 | D14: 84 | E14: 218 | F14: 134 | G14: 3.098 min | H14: α | I14: 0.9998 | J14: 6.115 | K14: — | L14: Pb-214 | M14: 8 | N14: 0.02% β⁻ branch → At-218
A15: U-238 Series | B15: Lead-214 | C15: Pb-214 | D15: 82 | E15: 214 | F15: 132 | G15: 26.8 min | H15: β⁻ | I15: 1 | J15: 1.032 | K15: 0.352 | L15: Bi-214 | M15: 9 | N15: Radon progeny; WL measurement nuclide
A16: U-238 Series | B16: Bismuth-214 | C16: Bi-214 | D16: 83 | E16: 214 | F16: 131 | G16: 19.9 min | H16: β⁻ | I16: 0.9998 | J16: 3.272 | K16: 0.609, 1.120, 1.764 | L16: Po-214 | M16: 10 | N16: 0.02% α branch → Tl-210; major γ emitter
A17: U-238 Series | B17: Polonium-214 | C17: Po-214 | D17: 84 | E17: 214 | F17: 130 | G17: 164.3 μs | H17: α | I17: 1 | J17: 7.833 | K17: — | L17: Pb-210 | M17: 11 | N17: Extremely short-lived; highest α energy in chain
A18: U-238 Series | B18: Lead-210 | C18: Pb-210 | D18: 82 | E18: 210 | F18: 128 | G18: 22.20 y | H18: β⁻ | I18: 1 | J18: 0.064 | K18: 0.047 | L18: Bi-210 | M18: 12 | N18: Environmental tracer; sediment dating
A19: U-238 Series | B19: Bismuth-210 | C19: Bi-210 | D19: 83 | E19: 210 | F19: 127 | G19: 5.013 d | H19: β⁻ | I19: 1 | J19: 1.163 | K19: — | L19: Po-210 | M19: 13 | N19: ~1.3×10⁻⁴% α branch to Tl-206
A20: U-238 Series | B20: Polonium-210 | C20: Po-210 | D20: 84 | E20: 210 | F20: 126 | G20: 138.376 d | H20: α | I20: 1 | J20: 5.407 | K20: 0.803 | L20: Pb-206 (STABLE) | M20: 14 | N20: Litvinenko poisoning agent; end of U-238 chain
A21: U-238 Series | B21: Lead-206 | C21: Pb-206 | D21: 82 | E21: 206 | F21: 124 | G21: STABLE | H21: — | I21: — | J21: — | K21: — | L21: — | M21: End | N21: ★ Stable end product of U-238 series
A23: URANIUM-235 SERIES (4n+3) | N23: Also called Actinium series; ends at Pb-207
A24: U-235 Series | B24: Uranium-235 | C24: U-235 | D24: 92 | E24: 235 | F24: 143 | G24: 7.038 × 10⁸ y | H24: α | I24: 1 | J24: 4.679 | K24: 0.186 | L24: Th-231 | M24: 1 | N24: Fissile isotope (0.72% natural U); γ at 186 keV
A25: U-235 Series | B25: Thorium-231 | C25: Th-231 | D25: 90 | E25: 231 | F25: 141 | G25: 25.52 h | H25: β⁻ | I25: 1 | J25: 0.389 | K25: 0.026 | L25: Pa-231 | M25: 2 | N25: Short-lived; secular equilibrium
A26: U-235 Series | B26: Protactinium-231 | C26: Pa-231 | D26: 91 | E26: 231 | F26: 140 | G26: 3.276 × 10⁴ y | H26: α | I26: 1 | J26: 5.149 | K26: 0.027, 0.283, 0.330 | L26: Ac-227 | M26: 3 | N26: Series namesake; ocean tracer (Pa/Th dating)
A27: U-235 Series | B27: Actinium-227 | C27: Ac-227 | D27: 89 | E27: 227 | F27: 138 | G27: 21.772 y | H27: β⁻ | I27: 0.9862 | J27: 0.045 | K27: — | L27: Th-227 | M27: 4 | N27: 1.38% α branch → Fr-223
A28: U-235 Series | B28: Thorium-227 | C28: Th-227 | D28: 90 | E28: 227 | F28: 137 | G28: 18.68 d | H28: α | I28: 1 | J28: 6.146 | K28: 0.236, 0.050 | L28: Ra-223 | M28: 5 | N28: Transient equilibrium with Ac-227
A29: U-235 Series | B29: Radium-223 | C29: Ra-223 | D29: 88 | E29: 223 | F29: 135 | G29: 11.43 d | H29: α | I29: 1 | J29: 5.979 | K29: 0.154, 0.269, 0.324 | L29: Rn-219 | M29: 6 | N29: Xofigo® (Ra-223 dichloride) cancer therapy
A30: U-235 Series | B30: Radon-219 | C30: Rn-219 | D30: 86 | E30: 219 | F30: 133 | G30: 3.96 s | H30: α | I30: 1 | J30: 6.946 | K30: 0.271, 0.402 | L30: Po-215 | M30: 7 | N30: Also called actinon; very short-lived noble gas
A31: U-235 Series | B31: Polonium-215 | C31: Po-215 | D31: 84 | E31: 215 | F31: 131 | G31: 1.781 ms | H31: α | I31: 0.9999977 | J31: 7.526 | K31: — | L31: Pb-211 | M31: 8 | N31: ~2.3×10⁻⁴% β⁻ branch → At-215
A32: U-235 Series | B32: Lead-211 | C32: Pb-211 | D32: 82 | E32: 211 | F32: 129 | G32: 36.1 min | H32: β⁻ | I32: 1 | J32: 1.367 | K32: 0.405, 0.427, 0.832 | L32: Bi-211 | M32: 9 | N32: Radon-219 progeny
A33: U-235 Series | B33: Bismuth-211 | C33: Bi-211 | D33: 83 | E33: 211 | F33: 128 | G33: 2.14 min | H33: α | I33: 0.99724 | J33: 6.751 | K33: 0.351 | L33: Tl-207 | M33: 10 | N33: 0.276% β⁻ branch → Po-211
A34: U-235 Series | B34: Thallium-207 | C34: Tl-207 | D34: 81 | E34: 207 | F34: 126 | G34: 4.77 min | H34: β⁻ | I34: 1 | J34: 1.423 | K34: 0.897 | L34: Pb-207 (STABLE) | M34: 11 | N34: Final β⁻ decay to stable lead
A35: U-235 Series | B35: Lead-207 | C35: Pb-207 | D35: 82 | E35: 207 | F35: 125 | G35: STABLE | H35: — | I35: — | J35: — | K35: — | L35: — | M35: End | N35: ★ Stable end product of U-235 series
A37: THORIUM-232 SERIES (4n) | N37: Also called Thorium series; ends at Pb-208
A38: Th-232 Series | B38: Thorium-232 | C38: Th-232 | D38: 90 | E38: 232 | F38: 142 | G38: 1.405 × 10¹⁰ y | H38: α | I38: 1 | J38: 4.083 | K38: 0.059 | L38: Ra-228 | M38: 1 | N38: Primordial; 3× more abundant than uranium
A39: Th-232 Series | B39: Radium-228 | C39: Ra-228 | D39: 88 | E39: 228 | F39: 140 | G39: 5.75 y | H39: β⁻ | I39: 1 | J39: 0.046 | K39: — | L39: Ac-228 | M39: 2 | N39: Also called mesothorium 1
A40: Th-232 Series | B40: Actinium-228 | C40: Ac-228 | D40: 89 | E40: 228 | F40: 139 | G40: 6.15 h | H40: β⁻ | I40: 1 | J40: 2.127 | K40: 0.338, 0.911, 0.969 | L40: Th-228 | M40: 3 | N40: Strong γ emitter; environmental tracer
A41: Th-232 Series | B41: Thorium-228 | C41: Th-228 | D41: 90 | E41: 228 | F41: 138 | G41: 1.9116 y | H41: α | I41: 1 | J41: 5.52 | K41: 0.084 | L41: Ra-224 | M41: 4 | N41: Also called radiothorium
A42: Th-232 Series | B42: Radium-224 | C42: Ra-224 | D42: 88 | E42: 224 | F42: 136 | G42: 3.66 d | H42: α | I42: 1 | J42: 5.789 | K42: 0.241 | L42: Rn-220 | M42: 5 | N42: Source of thoron (Rn-220)
A43: Th-232 Series | B43: Radon-220 | C43: Rn-220 | D43: 86 | E43: 220 | F43: 134 | G43: 55.6 s | H43: α | I43: 1 | J43: 6.404 | K43: 0.55 | L43: Po-216 | M43: 6 | N43: Also called thoron; indoor air contributor
...

Sheet Degradation Products
B2: Radiation Degradation Products — Radiolysis, Activation, Decay Chains & Secondary Radiation
B3: Covers: water radiolysis products | neutron activation products | radioactive decay chains | secondary particle generation
B5: A. CORE DECAY & ACTIVATION EQUATIONS
B6: Equation Name | C6: Formula | D6: Variables | E6: Source | F6: Application
B7: Radioactive Decay Law | C7: A(t) = A₀ · exp(−λt) N(t) = N₀ · exp(−λt) | D7: A=activity (Bq); λ=ln2/T½; t=time; N=atom count | E7: Rutherford (1905); ICRP 107 | F7: Activity of any single radionuclide vs time; secular equilibrium check
B8: Bateman Equation (parent→daughter) | C8: A₂(t) = A₁(0)·[λ₂/(λ₂−λ₁)]·(exp(−λ₁t) − exp(−λ₂t)) | D8: λ₁=parent decay const; λ₂=daughter decay const; A₁(0)=initial parent activity | E8: Bateman (1910); ICRP 107; NNDC | F8: Two-member decay chains: Mo-99/Tc-99m, Ra-226/Rn-222, U-238 chain
B9: Secular Equilibrium | C9: A_daughter ≈ A_parent (when T½_parent >> T½_daughter) | D9: Condition: λ_parent << λ_daughter; reached after ~7 × T½_daughter | E9: ICRP 38; NNDC NuDat | F9: Long-lived parent dominates: U-238→Ra-226→Rn-222; Cs-137→Ba-137m
B10: Transient Equilibrium | C10: A₂/A₁ = λ₂/(λ₂−λ₁) = const (after equilibrium) | D10: Condition: T½_parent > T½_daughter by factor 10–100 | E10: ICRP 38; Bateman 1910 | F10: Mo-99→Tc-99m (T½: 66h→6h); generator systems
B11: Neutron Activation | C11: A(t) = N · σ · Φ · (1 − exp(−λt)) | D11: N=target atoms; σ=cross section (cm²); Φ=neutron flux (n/cm²/s); λ=product decay const | E11: IAEA TRS-424; ENDF; JEFF | F11: Reactor activation products: Co-60, Fe-55, Ni-63, H-3, C-14
B12: Saturation Activity | C12: A_sat = N · σ · Φ | D12: Maximum activity at long irradiation (t >> T½); t→∞ limit of activation equation | E12: ENDF; JEFF; IAEA | F12: Maximum Co-60 or Ni-63 production in structural steel after reactor irradiation
B13: Effective Half-Life (internal) | C13: T_eff = (T_phys · T_biol) / (T_phys + T_biol) λ_eff = λ_phys + λ_biol | D13: T_phys=physical half-life; T_biol=biological half-life for excretion from organ | E13: ICRP 30; ICRP 68 | F13: I-131 in thyroid: T_phys=8d, T_biol=120d → T_eff≈7.3d; H-3 in body water
B14: S-Value (internal dosimetry) | C14: S(T←S) = Σᵢ Δᵢ · SAF(T←S, Eᵢ) / mT | D14: Δᵢ=mean energy emitted per decay; SAF=specific absorbed fraction; mT=target mass | E14: ICRP 133; MIRD Pamphlet 11 | F14: Internal absorbed dose to organ T from source organ S per unit activity
B15: Committed Dose from Intake | C15: E(50) = e(50) · Intake [Bq] e(50) in Sv/Bq from ICRP 68/130 | D15: e(50) = dose coefficient [Sv/Bq]; Intake = activity taken in | E15: ICRP 68; ICRP 130; EPA FGR 11 | F15: Worker dose from I-131 inhalation, Cs-137 ingestion, Pu-239 inhalation
B16: Water Radiolysis G-value | C16: G(product) = moles product / 100 eV absorbed G(•OH)=0.28; G(e⁻aq)=0.27; G(H₂O₂)=0.075 | D16: G = chemical yield; units μmol/J; varies with LET (low LET: γ; high LET: α) | E16: Spinks & Woods 1990; NIST; Allen 1961 | F16: Reactor coolant chemistry; H₂O₂ corrosion; steel/polymer radiation damage
B19: B. CORE DOCUMENTS — RADIOLYSIS, ACTIVATION PRODUCTS & DECAY CHAINS
B20: Document | C20: Author/Publisher | D20: Year | E20: Type | F20: Content Summary | G20: Products / Species Covered | H20: URL
B21: Spinks & Woods: An Introduction to Radiation Chemistry | C21: Wiley (3rd ed.) | D21: 1990 | E21: ★ Textbook | F21: Definitive radiation chemistry textbook; G-values; LET effects; radical reactions; polymer degradation | G21: •OH, e⁻aq, •H, H₂, H₂O₂, HO₂•; organic radicals; O₂ reactions | H21: → Link
B22: Allen: The Radiation Chemistry of Water and Aqueous Solutions | C22: Van Nostrand | D22: 1961 | E22: Textbook | F22: Classical treatment of water radiolysis; primary yields; ionic products; temperature effects | G22: H₂O⁺, OH⁻, H₃O⁺; primary radiolytic products; pH effects | H22: → Link
B23: ICRP 38: Radionuclide Transformations | C23: ICRP | D23: 1983 | E23: ★ Data Reference | F23: Complete decay data for dosimetric radionuclides; daughter products; branching fractions | G23: All α,β,γ,X emitters; decay chain products; secular/transient equilibrium data | H23: → Link
B24: ICRP 107: Nuclear Decay Data for Dosimetric Calculations | C24: ICRP | D24: 2008 | E24: ★ Data Reference | F24: Updated decay data for 1252 radionuclides; Auger electrons; IC electrons; complete decay tables | G24: All dosimetrically significant radionuclides including activation products | H24: → Link
B25: NNDC Chart of Nuclides / NuDat 3.0 | C25: Brookhaven National Lab | D25: 2023 | E25: ★ Database | F25: Online nuclide decay data: half-lives, decay modes, γ-ray energies, parent-daughter chains | G25: All 3300+ known nuclides; fission products; activation products; natural decay chains | H25: → Link
B26: ORIGEN-S / SCALE (ORNL) | C26: Oak Ridge National Lab | D26: 2018 | E26: ★ Code/Data | F26: Activation/depletion code system; full fission product chains; activation inventories; source term | G26: Fission products: Xe-133, I-131, Cs-137, Sr-90; structural activation: Co-60, Fe-55 | H26: → Link
B27: FISPACT-II (UKAEA) | C27: UKAEA/Culham | D27: 2017 | E27: Code/Data | F27: Inventory code for activation and transmutation; uses TENDL/JEFF cross sections | G27: Activation of metals: Al, Fe, Ni, Cu, Mo; medical isotope production | H27: → Link
B28: IAEA TECDOC-1234: Clearance of Materials Resulting from Use of Radionuclides | C28: IAEA | D28: 2004 | E28: Technical Doc | F28: Clearance levels for radionuclides in solid materials; activation product inventories | G28: Co-60, Cs-137, H-3, C-14, Ni-63 in decommissioning waste streams | H28: → Link
B29: Ewing: The Chemistry of Nuclear Fuel Waste Disposal | C29: MRS | D29: 2004 | E29: Review | F29: Long-lived fission product chemistry; alpha-recoil damage; spent fuel radiolysis | G29: Long-lived fission products: Tc-99, I-129, Cs-135; actinides; radiolytic H₂ | H29: → Link
B30: Wishart & Spinks: Radiation Chemistry Fundamentals | C30: Springer | D30: 2010 | E30: Textbook | F30: Modern radiation chemistry; track structure; early kinetics; pulse radiolysis techniques | G30: Solvated electrons; radical intermediates; molecular product yields | H30: → Link
B31: Christodouleas et al.: Short-Term and Long-Term Health Risks of Nuclear-Power-Plant Accidents | C31: NEJM | D31: 2011 | E31: Medical Review | F31: Fission products and health effects; I-131, Cs-137, Sr-90 exposure pathways; thyroid dose | G31: I-131 (thyroid), Cs-137 (whole body), Sr-90 (bone), Ru-103; external vs internal | H31: → Link
... B41: NCRP 142: Operational Radiation Safety Program for Astronauts in LEO | C41: NCRP | D41: 2002 | E41: NCRP Report | F41: Space radiation: GCR, SPE; secondary neutrons and protons; HZE particles; shielding | G41: Secondary particles: neutrons, protons, pions, muons from GCR interactions with shielding | H41: → Link

Sheet Computational Tools
B2: Computational Tools — Monte Carlo Codes, Deterministic Solvers & Dosimetry Software
B3: Purple = Monte Carlo code | Orange = activation/inventory code | Blue = deterministic/analytical | Green = dosimetry software
B5: Code / Tool | C5: Developer | D5: Method | E5: Particle Types | F5: Energy Range | G5: Primary Applications | H5: Reference / URL
B6: MCNP6 (Monte Carlo N-Particle) | C6: Los Alamos NL (USA) | D6: Monte Carlo | E6: n, γ, e⁻, p, α, heavy ions, muons, 37 particle types | F6: 10⁻¹¹ MeV – 1 TeV | G6: Shielding, criticality, dosimetry, medical physics, nuclear security, detector design | H6: → Link
B7: GEANT4 | C7: CERN (international) | D7: Monte Carlo | E7: All particles; EM, hadronic, optical photons, ions | F7: 0 – TeV | G7: Radiotherapy, space radiation, HEP detector sim, nuclear medicine, shielding | H7: → Link
B8: FLUKA | C8: CERN + INFN (Italy) | D8: Monte Carlo | E8: n, γ, e⁻/+, μ, p, heavy ions, neutrinos | F8: 0.001 eV – 100 TeV | G8: High energy shielding, accelerator design, space dosimetry, activation products | H8: → Link
B9: EGSnrc / BEAMnrc | C9: NRC Canada + SLAC | D9: Monte Carlo | E9: e⁻, e⁺, γ; full Compton-Compton-Klein-Nishina | F9: 1 keV – 10 GeV | G9: Medical accelerator dosimetry, TPS validation, absorbed dose to water, film dosimetry | H9: → Link
B10: PENELOPE | C10: Univ. Barcelona / OECD-NEA | D10: Monte Carlo | E10: e⁻, e⁺, γ | F10: 50 eV – 1 GeV | G10: Low-energy electron dosimetry, brachytherapy, keV photon interactions, skin dosimetry | H10: → Link
B11: PHITS | C11: JAEA + RIST (Japan) | D11: Monte Carlo | E11: n, γ, e⁻/+, p, heavy ions, pions | F11: 0 – several TeV | G11: Space radiation, heavy ion therapy, activation, neutron dosimetry, nuclear medicine | H11: → Link
B12: TRIPOLI-4 | C12: CEA (France) | D12: Monte Carlo | E12: n, γ, e⁻/+ | F12: Thermal to 20 MeV | G12: Reactor physics, criticality, shielding, gamma transport, uncertainty analysis | H12: → Link
B13: SCALE 6.2 / ORIGEN-S | C13: Oak Ridge NL (USA) | D13: Deterministic + MC | E13: n, γ; depletion/activation | F13: Thermal to 20 MeV | G13: Fuel depletion, activation inventory, shielding, criticality, waste characterization | H13: → Link
B14: FISPACT-II | C14: UKAEA (UK) | D14: Deterministic | E14: n, p, d, γ, α activation | F14: Thermal to 200 MeV | G14: Activation of materials, fusion/fission component activation, clearance level calc | H14: → Link
B15: ACAB (Activation Code) | C15: UNED (Spain) | D15: Deterministic | E15: n, p, d, γ activation | F15: Thermal to 1 GeV | G15: Fusion material activation, waste characterization, dose rates from activated materials | H15: → Link
B16: DORT / TORT (Discrete Ordinates) | C16: Oak Ridge NL (USA) | D16: Deterministic SN | E16: n, γ | F16: Thermal to 20 MeV | G16: Deep penetration shielding, 2D/3D transport, reactor analysis | H16: → Link
... B25: MathCAD / MATLAB Templates (DOE) | C25: US DOE / various | D25: Analytical | E25: γ, β, n | F25: Applicable range | G25: Batch shielding calculations; ALI/DAC derivations; hand calculation verification templates | H25: → Link
